Workbook

Sheet Data Extraction
A1: Article ID | B1: Ryyan ID | C1: Dataset | D1: Papper | E1: DOI | F1: Titlle | G1: Year | H1: Objective of the Study (Researcher 1) | I1: Objective of the Study (AI Tool - OpenAI GPT) | J1: Objective of the Study (AI Tool - Anthropic Claude) | K1: Objective Codes (Researcher 1) | L1: Proposed Solution and Tracking Details (Researcher 1) | M1: Proposed Solution and Tracking Details (AI Tool - OpenAI GPT) | N1: Proposed Solution and Tracking Details (AI Tool - Anthropic Claude) | O1: What is being tracked? (Researcher 1) | P1: What is being tracked? (AI Tool - OpenAI GPT) | Q1: What is being tracked? (AI Tool - Anthropic Claude) | R1: Architecture Type (Researcher 1) | S1: Architecture Type (AI Tool - OpenAI GPT) | T1: Architecture Type (AI Tool - Anthropic Claude) | U1: Architecture Type | V1: Technology Stack (Researcher 1) | W1: Technology Stack (AI Tool - OpenAI GPT) | X1: Technology Stack (AI Tool - Anthropic Claude) | Y1: Purpose of Tracking (Researcher 1) | Z1: Purpose of Tracking (AI Tool - OpenAI GPT) | AA1: Purpose of Tracking (AI Tool - Anthropic Claude) | AB1: Responsibility Attribution (Researcher 1) | AC1: Responsibility Attribution (AI Tool - OpenAI GPT) | AD1: Responsibility Attribution (AI Tool - Anthropic Claude) | AE1: C1 (Researcher 1) | AF1: C1 - Value (AI Tool - OpenAI GPT) | AG1: C1 - Justification (AI Tool - OpenAI GPT) | AH1: C2 (Researcher 1) | AI1: C2 - Value (AI Tool - OpenAI GPT) | AJ1: C2 - Justification (AI Tool - OpenAI GPT) | AK1: C3 (Researcher 1) | AL1: C3 - Value (AI Tool - OpenAI GPT) | AM1: C3 - Justification (AI Tool - OpenAI GPT) | AN1: C4 (Researcher 1) | AO1: C4 - Value (AI Tool - OpenAI GPT) | AP1: C4 - Justification (AI Tool - OpenAI GPT) | AQ1: C5 (Researcher 1) | AR1: C5 - Value (AI Tool - OpenAI GPT) | AS1: C5 - Justification (AI Tool - OpenAI GPT) | AT1: C6 (Researcher 1) | AU1: C6 - Value (AI Tool - OpenAI GPT) | AV1: C6 - Justification (AI Tool - OpenAI GPT) | AW1: Research Method (Researcher 1) | AX1: Research Method (AI Tool - OpenAI GPT) | AY1: Evaluation Type (Researcher 1) | AZ1: Evaluation Type (AI Tool - OpenAI GPT) | BA1: Main Findings and Conclusions (Researcher 1) | BB1: Main Findings and Conclusions (AI Tool - OpenAI GPT) | BC1: Main Findings and Conclusions (AI Tool - Anthropic Claude) | BD1: Study Limitations (Researcher 1) | BE1: Study Limitations (AI Tool - OpenAI GPT) | BF1: Study Limitations (AI Tool - Anthropic Claude) | BG1: Notes (Researcher 1) | BH1: Notes (AI Tool - OpenAI GPT)
A2: 2-s2.0-84949513306 | B2: =VLOOKUP(A2,'Data Set'!A:C,2,FALSE) -> rayyan-172029219 | C2: =VLOOKUP(A2,'Data Set'!A:D,3,FALSE) -> 0 | D2: P001 | E2: 10.1109/ACSAC.2000.898877 | F2: Security Architectures for Controlled Digital Information Dissemination | G2: 2000 | H2: To identify and classify application-level security architectures that enable controlled dissemination and tracking of digital information, particularly in Payment-Free Type (PFT) environments. | I2: To identify and define security architectures that enable controlled dissemination and tracking of digital information, particularly in Payment-Free Type (PFT) environments, thereby providing a secure framework for organizations to manage digital content distribution. | J2: To identify and define security architectures that enable controlled dissemination and tracking of digital information, particularly in Payment-Free Type (PFT) environments, thereby providing a secure framework for organizations to manage digital content distribution. | K2: digital rights management, information dissemination control, tracking architectures, use-control, watermarking, security policy enforcement | L2: The article proposes eight distinct application-level security architectures based on three factors: Virtual Machine (VM), Control Set (CS), and Distribution Style. These architectures are designed to provide control and/or tracking capabilities for digital information dissemination. Tracking is achieved through watermarking and use-control technologies embedded in digital containers and enforced via virtual machines. | M2: The study addresses the domain of digital information security, focusing on the problem of unauthorized dissemination in Payment-Free Type environments. It proposes eight application-level security architectures based on three core elements: virtual machine, control set, and distribution style. These architectures vary in their ability to control and track digital information dissemination. The paper compares their capabilities, merits, and limitations, and discusses mechanisms such as watermarking and use-control technologies. A comparative analysis is provided by mapping commercial off-the-shelf solutions to the proposed architectures, demonstrating their practical relevance and availability. | N2: The study addresses the domain of digital information security, focusing on the problem of unauthorized dissemination in Payment-Free Type environments. It proposes eight application-level security architectures based on three core elements: virtual machine, control set, and distribution style. These architectures vary in their ability to control and track digital information dissemination. The paper compares their capabilities, merits, and limitations, and discusses mechanisms such as watermarking and use-control technologies. A comparative analysis is provided by mapping commercial off-the-shelf solutions to the proposed architectures, demonstrating their practical relevance and availability. | O2: Digital information (documents, media, technical descriptions) disseminated across organizations or systems. | P2: Digital information and its re-dissemination paths | Q2: Digital information and its re-dissemination paths | R2: Server-centered (most architectures rely on external repositories or control centers for access management) | S2: hybrid | T2: Server-centered | U2: =_xlfn.XLOOKUP(A2,ArticlesArchitecture[[#This Row],[Article ID]],ArticlesArchitecture[[#This Row],[Theme (final decision)]]) -> Server-centered | V2: Conceptual models using: virtual machines, digital containers, embedded/external control sets, watermarking technologies, and use-control mechanisms. No actual implementation is described; the paper presents a taxonomy and conceptual framework. | W2: The proposed solution integrates virtual machines, digital containers, control sets, and watermarking technologies. Virtual machines act as secure environments for accessing digital content, enforcing usage restrictions such as disabling print or save functions. Digital containers encapsulate content with cryptographic protections and usage policies. Control sets define access rights and can be embedded, external, or fixed. Watermarking technologies enable tracking by embedding invisible identifiers into digital content. The paper discusses actual implementations through commercial solutions like Adobe PDF Merchant and IBM Cryptolope, indicating a mix of conceptual and applied models. | X2: The proposed solution integrates virtual machines, digital containers, control sets, and watermarking technologies. Virtual machines act as secure environments for accessing digital content, enforcing usage restrictions such as disabling print or save functions. Digital containers encapsulate content with cryptographic protections and usage policies. Control sets define access rights and can be embedded, external, or fixed. Watermarking technologies enable tracking by embedding invisible identifiers into digital content. The paper discusses actual implementations through commercial solutions like Adobe PDF Merchant and IBM Cryptolope, indicating a mix of conceptual and applied models. | Y2: To prevent unauthorized redistribution of digital content and to trace the origin and path of re-disseminated information, ensuring confidentiality and accountability in sensitive environments such as intelligence and B2B transactions. | Z2: Tracking is necessary to identify unauthorized re-dissemination of digital information and to attribute responsibility. It aims to enhance security by enabling traceability of digital content, thereby deterring misuse and supporting forensic investigations. Tracking complements control mechanisms by providing post-distribution oversight, especially in environments where content may be leaked despite preventive measures. | AA2: Tracking is necessary to identify unauthorized re-dissemination of digital information and to attribute responsibility. It aims to enhance security by enabling traceability of digital content, thereby deterring misuse and supporting forensic investigations. Tracking complements control mechanisms by providing post-distribution oversight, especially in environments where content may be leaked despite preventive measures. | AB2: Yes. Watermarking mechanisms are proposed to embed identifiers (e.g., author, recipient, distribution date) into digital content, enabling tracing of unauthorized dissemination. | AC2: Yes, the architectures support responsibility attribution through watermarking mechanisms that embed sender and recipient identities into digital content, enabling tracing of re-dissemination events. | AD2: Yes, the architectures support responsibility attribution through watermarking mechanisms that embed sender and recipient identities into digital content, enabling tracing of re-dissemination events. | AE2: False. Justification: The paper presents conceptual architectures and mechanisms but does not describe any real-world implementation or deployment. | AF2: TRUE | AG2: The paper discusses commercial implementations of the proposed architectures, such as Adobe PDF Merchant and IBM Cryptolope. | AH2: True. Justification: The paper introduces a novel taxonomy of eight security architectures and integrates existing technologies (e.g., watermarking, use-control) into a unified framework. | AI2: TRUE | AJ2: The paper introduces a novel taxonomy of eight security architectures for digital information dissemination. | AK2: False. Justification: No empirical evaluation, case study, or experiment is conducted. | AL2: FALSE | AM2: There is no structured empirical evaluation or data analysis presented in the paper. | AN2: False. Justification: The architectures are not validated in industrial or organizational contexts. | AO2: FALSE | AP2: The paper does not report validation in industrial settings, although it references commercial tools. | AQ2: True. Justification: The paper presents a conceptual classification and framework without proposing a specific solution or implementation. | AR2: FALSE | AS2: The paper presents both conceptual models and references to implemented solutions, not solely a conceptual framework. | AT2: False. Justification: The paper is analytical and structured, not based on personal experience or anecdotal evidence. | AU2: FALSE | AV2: The paper is based on systematic analysis and architectural design, not solely on author opinions or experiences. | AW2: Solution proposal | AX2: Solution proposal | AY2: - | AZ2: - | BA2: The authors identify eight distinct security architectures for controlled digital information dissemination, each defined by combinations of virtual machine presence, control set type, and distribution style. They argue that these architectures can support both control and tracking capabilities, and propose watermarking and use-control mechanisms as essential technologies. The paper also maps existing commercial solutions to the proposed architectures. | BB2: The study identifies eight distinct security architectures for controlled digital information dissemination, each with varying capabilities for control and tracking. It emphasizes the importance of combining use-control and watermarking mechanisms to achieve comprehensive security. The architectures are mapped to existing commercial solutions, demonstrating their practical applicability. The paper concludes that these architectures provide a foundational framework for future research and development in secure digital content distribution. | BC2: The study identifies eight distinct security architectures for controlled digital information dissemination, each with varying capabilities for control and tracking. It emphasizes the importance of combining use-control and watermarking mechanisms to achieve comprehensive security. The architectures are mapped to existing commercial solutions, demonstrating their practical applicability. The paper concludes that these architectures provide a foundational framework for future research and development in secure digital content distribution. | BD2: No empirical validation or implementation is provided. The effectiveness of the proposed architectures and mechanisms is not tested. Watermarking technologies are acknowledged as immature and potentially vulnerable to tampering. | BE2: The paper acknowledges that watermarking technologies are still immature and may not reliably support tracking in all scenarios, especially if the content is tampered with. It also notes that embedding unique watermarks for mass dissemination is not yet feasible. | BF2: The paper acknowledges that watermarking technologies are still immature and may not reliably support tracking in all scenarios, especially if the content is tampered with. It also notes that embedding unique watermarks for mass dissemination is not yet feasible. | BG2: The paper emphasizes the need for generalized security architectures in PFT environments and provides a layered approach to understanding objectives, mechanisms, and architectures. It serves as a foundational taxonomy for future research and development in secure digital dissemination. | BH2: The article provides a foundational taxonomy and practical mapping of security architectures but lacks empirical validation or quantitative analysis.
A3: 2-s2.0-0242456750 | B3: =VLOOKUP(A3,'Data Set'!A:C,2,FALSE) -> rayyan-172029208 | C3: =VLOOKUP(A3,'Data Set'!A:D,3,FALSE) -> 0 | D3: P002 | E3: 10.1145/507721.507722 | F3: Towards Usage Control Models: Beyond Traditional Access Control | G3: 2002 | H3: To develop the concept of Usage Control (UCON), a unified model that integrates traditional access control, trust management, and digital rights management to address emerging security and privacy issues in digital environments. | I3: To introduce and formalize the concept of Usage Control (UCON), which unifies and extends traditional access control, trust management, and digital rights management into a comprehensive model for controlling access to and usage of digital information objects. | J3: To introduce and formalize the concept of Usage Control (UCON), which unifies and extends traditional access control, trust management, and digital rights management into a comprehensive model for controlling access to and usage of digital information objects. | K3: usage control, access control, trust management, digital rights management, privacy | L3: The article proposes the UCON model, which integrates server-side and client-side reference monitors to control usage of digital objects. It introduces components such as subjects, objects, rights, authorization rules, conditions, and obligations to enable fine-grained control over digital object usage. Tracking includes usage logs, payment information, and reverse usage control mechanisms. | M3: The study operates within the domain of information security, addressing the limitations of traditional access control, trust management, and digital rights management in handling modern security and privacy challenges. The authors propose the Usage Control (UCON) model, which integrates these three paradigms to enable fine-grained control over digital object usage, including rights delegation and post-access obligations. The model introduces core components—subjects, objects, and rights—and additional components such as authorization rules, conditions, and obligations. UCON supports both server-side and client-side reference monitors, as well as hybrid architectures, allowing for flexible enforcement in both centralized and decentralized environments. Comparative analysis demonstrates how UCON encompasses and extends existing models like Mandatory Access Control, Discretionary Access Control, Role-Based Access Control, and commercial Digital Rights Management systems. | N3: The study operates within the domain of information security, addressing the limitations of traditional access control, trust management, and digital rights management in handling modern security and privacy challenges. The authors propose the Usage Control (UCON) model, which integrates these three paradigms to enable fine-grained control over digital object usage, including rights delegation and post-access obligations. The model introduces core components—subjects, objects, and rights—and additional components such as authorization rules, conditions, and obligations. UCON supports both server-side and client-side reference monitors, as well as hybrid architectures, allowing for flexible enforcement in both centralized and decentralized environments. Comparative analysis demonstrates how UCON encompasses and extends existing models like Mandatory Access Control, Discretionary Access Control, Role-Based Access Control, and commercial Digital Rights Management systems. | O3: Usage logs, payment information, digital object access and modification rights | P3: Digital information objects and their derivative objects, including usage logs and payment information. | Q3: Digital information objects and their derivative objects, including usage logs and payment information. | R3: Hybrid (user-centered and server-centered) | S3: hybrid | T3: Server-centered | U3: =_xlfn.XLOOKUP(A3,ArticlesArchitecture[[#This Row],[Article ID]],ArticlesArchitecture[[#This Row],[Theme (final decision)]]) -> Hybrid (user-centered and server-centered) | W3: The article presents a conceptual model rather than an implemented system. It discusses the integration of traditional access control mechanisms (e.g., Mandatory Access Control, Discretionary Access Control, Role-Based Access Control), trust management systems, and Digital Rights Management technologies. The model incorporates server-side and client-side reference monitors, and introduces new components such as obligations and conditions for authorization. Technologies like access control lists, capability lists, and credit-based authorization are referenced, but no specific platforms, programming languages, or software frameworks are detailed. | X3: The article presents a conceptual model rather than an implemented system. It discusses the integration of traditional access control mechanisms (e.g., Mandatory Access Control, Discretionary Access Control, Role-Based Access Control), trust management systems, and Digital Rights Management technologies. The model incorporates server-side and client-side reference monitors, and introduces new components such as obligations and conditions for authorization. Technologies like access control lists, capability lists, and credit-based authorization are referenced, but no specific platforms, programming languages, or software frameworks are detailed. | Y3: To enforce usage policies, ensure privacy protection, support payment-based and payment-free dissemination, and enable accountability in digital environments. | Z3: Tracking is necessary to enforce fine-grained control over the usage of digital objects, including access, modification, and delegation of rights. It aims to address emerging security and privacy challenges in both commercial and non-commercial environments by enabling dynamic and context-aware authorization processes. Tracking supports the enforcement of obligations (e.g., usage logging, payment agreements) and conditions (e.g., time/location constraints), thereby enhancing accountability, privacy protection, and secure dissemination of digital content. | AA3: Tracking is necessary to enforce fine-grained control over the usage of digital objects, including access, modification, and delegation of rights. It aims to address emerging security and privacy challenges in both commercial and non-commercial environments by enabling dynamic and context-aware authorization processes. Tracking supports the enforcement of obligations (e.g., usage logging, payment agreements) and conditions (e.g., time/location constraints), thereby enhancing accountability, privacy protection, and secure dissemination of digital content. | AB3: Yes; the model allows identification of responsible parties through obligations and reverse UCON mechanisms, such as usage logs and payment records. | AC3: The UCON model includes mechanisms for tracking obligations and conditions, such as usage logs and payment information, which can be used to identify responsible parties in case of data leakage. The concept of reverse UCON further enables attribution by treating derivative objects (e.g., logs) as trackable entities with associated rights and obligations. | AD3: The UCON model includes mechanisms for tracking obligations and conditions, such as usage logs and payment information, which can be used to identify responsible parties in case of data leakage. The concept of reverse UCON further enables attribution by treating derivative objects (e.g., logs) as trackable entities with associated rights and obligations. | AE3: False. Justification: The model is not implemented or applied in a real-world setting. | AF3: FALSE | AG3: The paper presents a conceptual model without evidence of real-world implementation or deployment. | AH3: True. Justification: The paper introduces a novel unified model (UCON) integrating three distinct access control paradigms. | AI3: TRUE | AJ3: The paper introduces a novel model called Usage Control (UCON) that unifies and extends existing access control paradigms. | AK3: False. Justification: No empirical evaluation is conducted; the paper is conceptual. | AL3: FALSE | AM3: There is no structured empirical evaluation or data analysis presented in the article. | AN3: False. Justification: No industrial validation is presented. | AO3: FALSE | AP3: The model is not evaluated in an industrial context; examples are illustrative rather than based on industrial validation. | AQ3: True. Justification: The paper presents a conceptual framework without implementation or empirical validation. | AR3: FALSE | AS3: The paper goes beyond a conceptual framework by detailing model components and mapping to existing systems, though it remains theoretical. | AT3: False. Justification: The paper is not based on author opinion or personal experience but on theoretical synthesis. | AU3: FALSE | AV3: The paper is not based solely on the authors’ opinions or experiences; it builds on existing literature and proposes a structured model. | AW3: Philosophical paper | AX3: Solution proposal | AY3: - | AZ3: - | BA3: UCON provides a unified framework for usage control that surpasses traditional access control models by integrating trust management and digital rights management. It supports fine-grained control, hybrid architectures, and privacy-sensitive applications. The model introduces reverse usage control to handle derivative objects and emphasizes the need for legal or voluntary enforcement mechanisms. | BB3: The UCON model offers a unified and systematic approach to access and usage control by integrating traditional access control, trust management, and digital rights management. It introduces new components such as obligations and conditions, enabling finer-grained and context-aware authorization. The model supports hybrid architectures and addresses both security and privacy concerns. It lays the foundation for future research in delegation and administration within usage control systems. | BC3: The UCON model offers a unified and systematic approach to access and usage control by integrating traditional access control, trust management, and digital rights management. It introduces new components such as obligations and conditions, enabling finer-grained and context-aware authorization. The model supports hybrid architectures and addresses both security and privacy concerns. It lays the foundation for future research in delegation and administration within usage control systems. | BD3: The model lacks implementation and empirical validation. Delegation of rights and administrative aspects are identified as areas for future research. | BE3: The model is conceptual and lacks implementation details. Delegation of rights and administrative mechanisms are identified as areas requiring further research and development. | BF3: The model is conceptual and lacks implementation details. Delegation of rights and administrative mechanisms are identified as areas requiring further research and development. | BG3: The paper is foundational in proposing the UCON model and has influenced subsequent research in usage control and digital rights management. | BH3: The article is foundational in proposing the UCON model but does not include empirical validation or implementation. It is suitable for theoretical and conceptual analysis.
A4: 2-s2.0-65449181169 | B4: =VLOOKUP(A4,'Data Set'!A:C,2,FALSE) -> rayyan-218686268 | C4: =VLOOKUP(A4,'Data Set'!A:D,3,FALSE) -> Forward.1 | D4: P003 | E4: 10.1145/1409540.1409592 | F4: Preventing Information Leakage between Collaborating Organisations | G4: 2008 | H4: To propose a trusted computing-based framework for secure inter-organizational data sharing | I4: To propose a secure system that prevents information leakage when sensitive content is shared between collaborating organisations, ensuring that only authorised users within the destination organisation can access the shared content. | J4: To propose a secure system that prevents information leakage when sensitive content is shared between collaborating organisations, ensuring that only authorised users within the destination organisation can access the shared content. | K4: trusted computing, enterprise rights management, data leakage prevention | L4: A domain-based access control model using TPM, trusted software agents, and master controllers | M4: The study addresses the problem of information leakage during inter-organisational collaboration, particularly when sensitive data is shared across organisational boundaries. The authors propose a novel solution that integrates trusted computing technologies to enforce access control and data protection. The system introduces the concept of global and dynamic domains, where devices are grouped and assigned cryptographic keys to restrict access to shared content. A master controller manages domain membership and enforces organisational policies. Comparative analysis with existing access control models highlights the limitations of traditional approaches and the advantages of the proposed system in preventing both internal and external data leakage. | N4: The study addresses the problem of information leakage during inter-organisational collaboration, particularly when sensitive data is shared across organisational boundaries. The authors propose a novel solution that integrates trusted computing technologies to enforce access control and data protection. The system introduces the concept of global and dynamic domains, where devices are grouped and assigned cryptographic keys to restrict access to shared content. A master controller manages domain membership and enforces organisational policies. Comparative analysis with existing access control models highlights the limitations of traditional approaches and the advantages of the proposed system in preventing both internal and external data leakage. | O4: Sensitive organizational content | P4: Sensitive organisational content and access credentials | Q4: Sensitive organisational content and access credentials | R4: Server-centered | S4: server-centered | T4: Server-centered | U4: =_xlfn.XLOOKUP(A4,ArticlesArchitecture[[#This Row],[Article ID]],ArticlesArchitecture[[#This Row],[Theme (final decision)]]) -> Server-centered | V4: Trusted Platform Module (TPM), TCG specs, domain keys, master controller; conceptual model only | W4: The proposed solution is built upon Trusted Computing Group (TCG) specifications, incorporating Trusted Platform Modules (TPMs) for secure storage and attestation. Trusted software agents are deployed on organisational devices and master controllers to enforce access policies and manage cryptographic keys. The system uses sealed storage, attestation identity keys, and mutual authentication protocols to ensure that only trusted devices and software environments can access protected content. The implementation is conceptual, with detailed descriptions of protocols and workflows, but no empirical deployment is reported. | X4: The proposed solution is built upon Trusted Computing Group (TCG) specifications, incorporating Trusted Platform Modules (TPMs) for secure storage and attestation. Trusted software agents are deployed on organisational devices and master controllers to enforce access policies and manage cryptographic keys. The system uses sealed storage, attestation identity keys, and mutual authentication protocols to ensure that only trusted devices and software environments can access protected content. The implementation is conceptual, with detailed descriptions of protocols and workflows, but no empirical deployment is reported. | Y4: To prevent internal and external leakage during inter-organizational sharing | Z4: Tracking is necessary to ensure that sensitive content shared between organisations is only accessible to authorised users and devices. It aims to prevent both accidental and intentional data leakage by enforcing strict access control policies and verifying the integrity of devices and software environments. This contributes to the broader goal of secure information sharing in collaborative settings. | AA4: Tracking is necessary to ensure that sensitive content shared between organisations is only accessible to authorised users and devices. It aims to prevent both accidental and intentional data leakage by enforcing strict access control policies and verifying the integrity of devices and software environments. This contributes to the broader goal of secure information sharing in collaborative settings. | AB4: Yes; domain keys and TPM binding enable traceability | AC4: Yes, the system enables identification of responsible parties through logging mechanisms and device-specific access control. Logs are stored in protected environments and can record sender identity, device IP, recipient details, and timestamps, which can be used to trace data access and potential leakage. | AD4: Yes, the system enables identification of responsible parties through logging mechanisms and device-specific access control. Logs are stored in protected environments and can record sender identity, device IP, recipient details, and timestamps, which can be used to trace data access and potential leakage. | AE4: False. No real-world implementation. | AF4: FALSE | AG4: The paper does not report a real-world deployment or application of the proposed system. | AH4: True. Novel domain-based access control model. | AI4: TRUE | AJ4: The paper introduces a novel solution integrating trusted computing for inter-organisational data protection. | AK4: False. No empirical evaluation. | AL4: FALSE | AM4: There is no structured data collection or empirical evaluation presented. | AN4: False. No industrial validation. | AO4: FALSE | AP4: The solution is not validated in an industrial context. | AQ4: True. Conceptual framework only. | AR4: FALSE | AS4: The paper presents a detailed conceptual model but also includes implementation-level details. | AT4: False. Not based on author experience. | AU4: FALSE | AV4: The paper is not based solely on author experience or opinion. | AW4: Opinion paper | AX4: Solution proposal | AY4: - | AZ4: - | BA4: The framework outlines a secure sharing model using trusted computing and domain keys | BB4: The proposed system effectively addresses the challenge of preventing information leakage between collaborating organisations by using trusted computing technologies. It introduces global and dynamic domains to control access and enforces organisational policies through a master controller. The system ensures that only authorised users can access shared content and that data cannot be leaked to unauthorised parties, even within the destination organisation. | BC4: The proposed system effectively addresses the challenge of preventing information leakage between collaborating organisations by using trusted computing technologies. It introduces global and dynamic domains to control access and enforces organisational policies through a master controller. The system ensures that only authorised users can access shared content and that data cannot be leaked to unauthorised parties, even within the destination organisation. | BD4: No implementation or empirical validation | BE4: The paper does not include empirical validation or real-world deployment of the proposed system. Implementation details are conceptual, and integration with existing authentication mechanisms is noted as outside the scope of the study. | BF4: The paper does not include empirical validation or real-world deployment of the proposed system. Implementation details are conceptual, and integration with existing authentication mechanisms is noted as outside the scope of the study. | BG4: Suggests future integration with monitoring and detection systems | BH4: The article provides a comprehensive conceptual framework for secure inter-organisational data sharing but lacks empirical evaluation or industrial validation.
A5: 2-s2.0-84864275237 | B5: =VLOOKUP(A5,'Data Set'!A:C,2,FALSE) -> rayyan-172029019 | C5: =VLOOKUP(A5,'Data Set'!A:D,3,FALSE) -> 0 | D5: P004 | E5: 10.1109/SPW.2012.19 | F5: Fog Computing: Mitigating Insider Data Theft Attacks in the Cloud | G5: 2012 | H5: To propose a novel approach for securing cloud data against insider threats using Fog computing, which combines user behavior profiling and decoy information to detect and mitigate unauthorized access. | I5: To propose a novel approach for securing data in cloud environments against insider threats by using decoy-based disinformation techniques integrated with user behavior profiling. | J5: To propose a novel approach for securing data in cloud environments against insider threats by using decoy-based disinformation techniques integrated with user behavior profiling. | K5: cloud security, insider threat detection, decoy technology, user behavior profiling | L5: The article proposes a security mechanism that monitors user behavior in the cloud to detect abnormal access patterns. Upon suspicion of unauthorized access, challenge questions are used for verification. If confirmed, a disinformation attack is launched by serving decoy data to the attacker. This approach integrates user behavior profiling and decoy document deployment to protect sensitive data. | M5: The study addresses the problem of insider data theft in cloud computing, a critical concern for businesses outsourcing data storage and computation. The authors propose a solution termed 'Fog Computing', which integrates offensive decoy technology and user behavior profiling to detect and mitigate unauthorized access. The system monitors access patterns and, upon detecting anomalies, verifies legitimacy through challenge questions. If access is deemed unauthorized, it launches a disinformation attack by delivering decoy data to the attacker. This approach is compared against traditional encryption and access control methods, which have proven insufficient. Experimental results in local file systems suggest that combining behavior profiling with decoy deployment significantly enhances detection accuracy and security. | N5: The study addresses the problem of insider data theft in cloud computing, a critical concern for businesses outsourcing data storage and computation. The authors propose a solution termed 'Fog Computing', which integrates offensive decoy technology and user behavior profiling to detect and mitigate unauthorized access. The system monitors access patterns and, upon detecting anomalies, verifies legitimacy through challenge questions. If access is deemed unauthorized, it launches a disinformation attack by delivering decoy data to the attacker. This approach is compared against traditional encryption and access control methods, which have proven insufficient. Experimental results in local file systems suggest that combining behavior profiling with decoy deployment significantly enhances detection accuracy and security. | O5: User access patterns and interactions with cloud-stored data, including search behavior and file access. | P5: User access patterns and interactions with data files, including decoy documents. | Q5: User access patterns and interactions with data files, including decoy documents. | R5: Server-centered | S5: user-centered | T5: User-centered | U5: =_xlfn.XLOOKUP(A5,ArticlesArchitecture[[#This Row],[Article ID]],ArticlesArchitecture[[#This Row],[Theme (final decision)]]) -> Server-centered | V5: Conceptual model using one-class support vector machines for behavior profiling, decoy document generation with HMAC verification, and integration of profiling with decoy deployment. No full implementation in cloud; experiments conducted in local file system. | W5: The proposed solution utilizes user behavior profiling through one-class support vector machines to model normal access patterns. Decoy documents are embedded with keyed-Hash Message Authentication Codes (HMACs) to verify authenticity and detect unauthorized access. These decoys are strategically placed in conspicuous directories and named enticingly to attract potential attackers. The system does not rely on real-time decoy generation but emphasizes conspicuous placement and integration with anomaly detection. The implementation is demonstrated in a local file system setting, suggesting applicability to cloud environments. | X5: The proposed solution utilizes user behavior profiling through one-class support vector machines to model normal access patterns. Decoy documents are embedded with keyed-Hash Message Authentication Codes (HMACs) to verify authenticity and detect unauthorized access. These decoys are strategically placed in conspicuous directories and named enticingly to attract potential attackers. The system does not rely on real-time decoy generation but emphasizes conspicuous placement and integration with anomaly detection. The implementation is demonstrated in a local file system setting, suggesting applicability to cloud environments. | Y5: To detect and prevent unauthorized access to sensitive cloud data, especially by malicious insiders, by identifying abnormal user behavior and triggering decoy-based disinformation responses. | Z5: Tracking is employed to detect abnormal access behaviors indicative of insider threats. By profiling legitimate user behavior and monitoring interactions with decoy files, the system aims to identify masqueraders and prevent data exfiltration. The tracking supports challenge-response mechanisms and enables the deployment of disinformation to protect sensitive data. | AA5: Tracking is employed to detect abnormal access behaviors indicative of insider threats. By profiling legitimate user behavior and monitoring interactions with decoy files, the system aims to identify masqueraders and prevent data exfiltration. The tracking supports challenge-response mechanisms and enables the deployment of disinformation to protect sensitive data. | AB5: Yes. The system uses challenge questions and behavior profiling to validate user identity and detect impersonation, allowing attribution of unauthorized access to masqueraders. | AC5: The approach does not explicitly attribute responsibility for data leakage but enables detection of unauthorized access through behavioral anomalies and decoy interaction, which may indirectly support attribution. | AD5: The approach does not explicitly attribute responsibility for data leakage but enables detection of unauthorized access through behavioral anomalies and decoy interaction, which may indirectly support attribution. | AE5: False. Justification: The proposed solution was tested in a local file system environment, not deployed in a real-world cloud setting. | AF5: TRUE | AG5: Experiments were conducted in a local file system setting to simulate real-world scenarios. | AH5: True. Justification: The paper introduces a novel integration of decoy technology and user behavior profiling for cloud security. | AI5: TRUE | AJ5: The paper introduces a novel concept called Fog Computing combining decoy technology and user profiling. | AK5: True. Justification: Experiments were conducted using simulated masquerader data and user models trained on real usage data. | AL5: TRUE | AM5: Structured experiments were performed using user data and simulated attacks. | AN5: False. Justification: No evidence of evaluation in an industrial or organizational context. | AO5: FALSE | AP5: No evidence of industrial validation or deployment in commercial cloud environments. | AQ5: False. Justification: The paper proposes and evaluates a concrete solution, not just a conceptual framework. | AR5: FALSE | AS5: The paper presents an implemented and tested approach, not just a conceptual framework. | AT5: False. Justification: The study is based on experimental data and not solely on author opinion or experience. | AU5: FALSE | AV5: The study is based on empirical data and not solely on author experience or opinion. | AW5: Validation research | AX5: Evaluation research | AY5: Laboratory experiment (machine or human) | AZ5: Controlled experiment with practitioners | BA5: The combination of user behavior profiling and decoy technology significantly improves the detection of masquerade attacks. The approach can effectively confuse attackers and protect sensitive data, suggesting its potential applicability in cloud environments. | BB5: Combining user behavior profiling with decoy technology significantly improves the detection of masquerade attacks. The approach reduces false positives and enhances security by confusing attackers and validating alerts. The results suggest that this method could be effectively applied in cloud environments. | BC5: Combining user behavior profiling with decoy technology significantly improves the detection of masquerade attacks. The approach reduces false positives and enhances security by confusing attackers and validating alerts. The results suggest that this method could be effectively applied in cloud environments. | BD5: The solution was only tested in a local file system, not in an actual cloud environment. Decoys were pre-generated rather than dynamically created at detection time. | BE5: The experiments were conducted in a local file system setting, not in actual cloud environments. Real-time decoy generation was not implemented, and industrial validation is lacking. | BF5: The experiments were conducted in a local file system setting, not in actual cloud environments. Real-time decoy generation was not implemented, and industrial validation is lacking. | BG5: The study was supported by DARPA under the ADAMS and MRC programs. The authors suggest future work to implement the approach in real cloud systems. | BH5: The paper is a position paper supported by DARPA and includes references to prior technical reports and experiments.
A6: 2-s2.0-84918536488 | B6: =VLOOKUP(A6,'Data Set'!A:C,2,FALSE) -> rayyan-172029046 | C6: =VLOOKUP(A6,'Data Set'!A:D,3,FALSE) -> 0 | D6: P005 | E6: 10.1109/MEC.2013.6885474 | F6: A Distribution Model for Data Leakage Prevention | G6: 2013 | H6: To present a file distribution model that minimizes data leakage by considering user guilt probability | I6: To propose a file distribution model that minimizes data leakage by incorporating user guilt probability into the allocation strategy. | J6: To propose a file distribution model that minimizes data leakage by incorporating user guilt probability into the allocation strategy. | K6: data leakage prevention, cloud security, trust management | L6: A file allocation strategy that minimizes overlap in file sets among users, using guilt probability to identify potential leakers | M6: The study addresses the problem of sensitive data leakage in cloud computing environments. It proposes a distribution model that integrates user guilt probability—a metric indicating the likelihood of a user leaking data—into the file allocation strategy. The model aims to minimize the overlap of file sets among users, thereby enhancing the ability to trace the source of data leakage. Compared to previous models, this approach improves the accuracy of identifying malicious users and enhances information security through simulation-based validation. | N6: The study addresses the problem of sensitive data leakage in cloud computing environments. It proposes a distribution model that integrates user guilt probability—a metric indicating the likelihood of a user leaking data—into the file allocation strategy. The model aims to minimize the overlap of file sets among users, thereby enhancing the ability to trace the source of data leakage. Compared to previous models, this approach improves the accuracy of identifying malicious users and enhances information security through simulation-based validation. | O6: Sensitive files in cloud environments | P6: Sensitive data files distributed to users | Q6: Sensitive data files distributed to users | R6: Server-centered | S6: server-centered | T6: Server-centered | U6: =_xlfn.XLOOKUP(A6,ArticlesArchitecture[[#This Row],[Article ID]],ArticlesArchitecture[[#This Row],[Theme (final decision)]]) -> Server-centered | V6: Conceptual model using guilt probability, simulation-based validation; no implementation stack specified | W6: The proposed solution is conceptual and algorithmic in nature. It includes a multi-round file distribution strategy that uses guilt probability metrics to guide allocation decisions. The system comprises algorithms such as FirstDis, NextDis, DistOneDis, and MinimumSum, which collectively determine optimal file distribution plans. The model is implemented and validated through simulation experiments, but no specific programming languages, platforms, or frameworks are mentioned, indicating a conceptual rather than a fully implemented system. | X6: The proposed solution is conceptual and algorithmic in nature. It includes a multi-round file distribution strategy that uses guilt probability metrics to guide allocation decisions. The system comprises algorithms such as FirstDis, NextDis, DistOneDis, and MinimumSum, which collectively determine optimal file distribution plans. The model is implemented and validated through simulation experiments, but no specific programming languages, platforms, or frameworks are mentioned, indicating a conceptual rather than a fully implemented system. | Y6: To identify malicious users and prevent further leakage | Z6: Tracking is employed to identify potential sources of data leakage by analyzing the distribution of sensitive files and calculating user guilt probabilities. This enables the system to distinguish between honest, common, and malicious users, thereby supporting preventive measures and enhancing data security. | AA6: Tracking is employed to identify potential sources of data leakage by analyzing the distribution of sensitive files and calculating user guilt probabilities. This enables the system to distinguish between honest, common, and malicious users, thereby supporting preventive measures and enhancing data security. | AB6: Yes; based on guilt probability model | AC6: Yes, the model enables identification of responsible parties through the guilt probability metric, which helps infer the likelihood of a user being the source of a data leak. | AD6: Yes, the model enables identification of responsible parties through the guilt probability metric, which helps infer the likelihood of a user being the source of a data leak. | AE6: False. No real-world implementation. | AF6: FALSE | AG6: The model is validated through simulation experiments, not applied in a real-world setting. | AH6: True. Novel guilt-based model. | AI6: TRUE | AJ6: The paper introduces a novel distribution model incorporating guilt probability for data leakage prevention. | AK6: True. Simulation-based evaluation. | AL6: TRUE | AM6: Structured simulation experiments are conducted to evaluate the model's effectiveness. | AN6: False. No industrial validation. | AO6: FALSE | AP6: There is no evidence of industrial validation; the evaluation is limited to simulations. | AQ6: False. Not philosophical. | AR6: FALSE | AS6: The paper presents a detailed algorithmic model and simulation results, not just a conceptual framework. | AT6: False. Not based on author experience. | AU6: FALSE | AV6: The study is based on algorithmic development and simulation, not solely on author experience or opinion. | AW6: Validation research | AX6: Validation research | AY6: Simulation as an empirical method | AZ6: Simulation | BA6: The model effectively distinguishes malicious users and identifies leak sources with high probability | BB6: The proposed distribution model effectively identifies malicious users by leveraging guilt probability. Simulation results show that incorporating guilt probability increases the differentiation between user types, thereby improving the accuracy of leak source detection and enhancing data security. | BC6: The proposed distribution model effectively identifies malicious users by leveraging guilt probability. Simulation results show that incorporating guilt probability increases the differentiation between user types, thereby improving the accuracy of leak source detection and enhancing data security. | BD6: No real-world deployment; simulation only | BE6: The model is tested only in simulated environments; practical deployment and real-world validation are not addressed. | BF6: The model is tested only in simulated environments; practical deployment and real-world validation are not addressed. | BG6: Guilt probability enhances traceability in cloud file distribution | BH6: The article provides a simulation-based validation of a conceptual model. No implementation details such as programming languages or platforms are provided.
A7: 2-s2.0-84942810277 | B7: =VLOOKUP(A7,'Data Set'!A:C,2,FALSE) -> rayyan-218688840 | C7: =VLOOKUP(A7,'Data Set'!A:D,3,FALSE) -> Backward.1 | D7: P006 | E7: 10.1049/cje.2015.10.033 | F7: EABDS: Attribute-Based Secure Data Sharing with Efficient Revocation in Cloud Computing | G7: 2015 | H7: To propose an attribute-based encryption scheme with efficient revocation and escrow-free key management for cloud data sharing. | I7: To propose a secure data sharing scheme in cloud computing that ensures data confidentiality, efficient revocation, and fine-grained access control using attribute-based encryption. | J7: To propose a secure data sharing scheme in cloud computing that ensures data confidentiality, efficient revocation, and fine-grained access control using attribute-based encryption. | K7: cloud security, attribute-based encryption, key revocation, access control | L7: EABDS encrypts data using CP-ABE and DEK, with homomorphic encryption for key generation. Revocation is handled via key server updates and ciphertext re-encryption. | M7: The study addresses the problem of secure data sharing in cloud computing, particularly focusing on data confidentiality, access control, and key escrow issues. It introduces the EABDS scheme, which combines symmetric encryption with Ciphertext-Policy Attribute-Based Encryption (CP-ABE) to protect data. The scheme uses additively homomorphic encryption to collaboratively generate attribute secret keys by the attribute authority and key server, thereby mitigating the key escrow problem. It also incorporates an immediate attribute revocation mechanism that ensures both forward and backward security. Comparative analysis shows that EABDS reduces computational overhead on users and improves security and efficiency compared to existing schemes. | N7: The study addresses the problem of secure data sharing in cloud computing, particularly focusing on data confidentiality, access control, and key escrow issues. It introduces the EABDS scheme, which combines symmetric encryption with Ciphertext-Policy Attribute-Based Encryption (CP-ABE) to protect data. The scheme uses additively homomorphic encryption to collaboratively generate attribute secret keys by the attribute authority and key server, thereby mitigating the key escrow problem. It also incorporates an immediate attribute revocation mechanism that ensures both forward and backward security. Comparative analysis shows that EABDS reduces computational overhead on users and improves security and efficiency compared to existing schemes. | O7: Encrypted cloud data (DEK and CP-ABE ciphertexts) | P7: Data encryption keys and user attributes for access control | Q7: Data encryption keys and user attributes for access control | R7: Server-centered | S7: hybrid | T7: Server-centered | U7: =_xlfn.XLOOKUP(A7,ArticlesArchitecture[[#This Row],[Article ID]],ArticlesArchitecture[[#This Row],[Theme (final decision)]]) -> Server-centered | V7: CP-ABE, homomorphic encryption, bilinear maps, symmetric encryption | W7: The proposed solution integrates symmetric encryption for data protection and Ciphertext-Policy Attribute-Based Encryption (CP-ABE) for access control. It employs additively homomorphic encryption to enable collaborative key generation between the attribute authority and key server, preventing any single entity from accessing the full attribute secret keys. The system uses bilinear maps and elliptic curve cryptography, implemented via a pairing-based cryptography library. The architecture is practically implemented and simulated on a virtual machine using Ubuntu 12.10, demonstrating its computational efficiency. | X7: The proposed solution integrates symmetric encryption for data protection and Ciphertext-Policy Attribute-Based Encryption (CP-ABE) for access control. It employs additively homomorphic encryption to enable collaborative key generation between the attribute authority and key server, preventing any single entity from accessing the full attribute secret keys. The system uses bilinear maps and elliptic curve cryptography, implemented via a pairing-based cryptography library. The architecture is practically implemented and simulated on a virtual machine using Ubuntu 12.10, demonstrating its computational efficiency. | Y7: To ensure fine-grained access control, forward/backward secrecy, and prevent key escrow in cloud environments. | Z7: Tracking is necessary to enforce fine-grained access control, ensure data confidentiality, and support secure revocation of user attributes. It enables the system to determine whether a user possesses the required attributes to decrypt data, thereby preventing unauthorized access and ensuring that revoked users cannot access past or future data. | AA7: Tracking is necessary to enforce fine-grained access control, ensure data confidentiality, and support secure revocation of user attributes. It enables the system to determine whether a user possesses the required attributes to decrypt data, thereby preventing unauthorized access and ensuring that revoked users cannot access past or future data. | AB7: Yes. Malicious entities can be identified via access control logs and key server records. | AC7: Yes, the scheme enables identification of responsible parties in case of data leakage by ensuring that attribute secret keys are uniquely generated for each user through collaboration between the attribute authority and key server. | AD7: Yes, the scheme enables identification of responsible parties in case of data leakage by ensuring that attribute secret keys are uniquely generated for each user through collaboration between the attribute authority and key server. | AE7: True. Scheme implemented and tested. | AF7: TRUE | AG7: The scheme is implemented and simulated in a virtual environment using real cryptographic libraries. | AH7: True. Novel escrow-free CP-ABE with revocation. | AI7: TRUE | AJ7: The paper introduces a novel scheme (EABDS) combining CP-ABE with homomorphic encryption for secure data sharing. | AK7: True. Performance and security analysis conducted. | AL7: TRUE | AM7: The paper includes performance simulations comparing encryption and decryption times with existing schemes. | AN7: False. No industrial deployment. | AO7: FALSE | AP7: There is no evidence of evaluation in an industrial context; the validation is academic. | AQ7: False. Not conceptual only. | AR7: FALSE | AS7: The paper presents a fully constructed and implemented solution, not just a conceptual framework. | AT7: False. Not based on personal experience. | AU7: FALSE | AV7: The paper is based on technical implementation and analysis, not solely on author experience or opinion. | AW7: Evaluation research | AX7: Evaluation research | AY7: Mathematical analysis and proof of properties | AZ7: Simulation | BA7: EABDS achieves secure, efficient, and revocable data sharing with reduced user overhead and strong privacy guarantees. | BB7: The EABDS scheme effectively addresses key escrow and attribute revocation challenges in cloud computing. It ensures data confidentiality, supports fine-grained access control, and reduces computational overhead on users by delegating decryption tasks to a key server. Compared to existing schemes, EABDS offers improved security and efficiency. | BC7: The EABDS scheme effectively addresses key escrow and attribute revocation challenges in cloud computing. It ensures data confidentiality, supports fine-grained access control, and reduces computational overhead on users by delegating decryption tasks to a key server. Compared to existing schemes, EABDS offers improved security and efficiency. | BD7: No real-world deployment; simulation-based validation only. | BE7: The scheme assumes semi-trusted entities and does not address scenarios where the attribute authority and key server collude. It also excludes protection for data after successful decryption by users. | BF7: The scheme assumes semi-trusted entities and does not address scenarios where the attribute authority and key server collude. It also excludes protection for data after successful decryption by users. | BG7: Compared against existing schemes for revocation and escrow. | BH7: The article provides a detailed construction and simulation of the proposed scheme, making it suitable for practical application in secure cloud data sharing.
